<?xml version="1.0" encoding="utf-8"?>
<!--
Usage:

<mujoco>
	<compiler meshdir="../meshes/sawyer" ...></compiler>
	<include file="shared_config.xml"></include>
    (new stuff)
	<worldbody>
		<include file="sawyer_xyz_base.xml"></include>
        (new stuff)
	</worldbody>
</mujoco>
-->

<mujoco model="sawyer">
    <camera pos="0 0 3.2" name="topview" />

    <geom name="tableTop" type="plane" pos="0 0.6 0" size="0.4 0.4 0.5"
          rgba=".6 .6 .5 1" contype="1" conaffinity="1" friction="2 0.1 0.002" material="light_wood_v3"/>

<!--        <body name="robot0_link0" pos="0 0 0" quat="0.707107 0 0 0.707107">-->
<!--        <body name="robot0_link0" pos="0 0 0" quat="0 0 0 1">-->
    <body name="base" pos="0 0 0">
        <inertial diaginertia="0 0 0" mass="0" pos="0 0 0"/>
        <body name="controller_box" pos="0 0 0">
            <inertial diaginertia="1.71363 1.27988 0.809981" mass="46.64" pos="-0.325 0 -0.38"/>
            <geom pos="-0.325 0 -0.38" size="0.11 0.2 0.265" type="box" name="controller_box_col"/>
        </body>
        <body name="pedestal_feet" pos="0 0 0">
            <inertial diaginertia="8.16095 9.59375 15.0785" mass="167.09" pos="-0.1225 0 -0.758"/>
            <geom pos="-0.1225 0 -0.758" size="0.385 0.35 0.155" type="box" name="pedestal_feet_col"/>
        </body>
        <body name="torso" pos="0 0 0">
            <inertial diaginertia="1e-08 1e-08 1e-08" mass="0.0001" pos="0 0 0"/>
            <geom conaffinity="0" contype="0" group="1" rgba="0.2 0.2 0.2 1" size="0.05 0.05 0.05" type="box" name="torso_col"/>
        </body>
        <body name="pedestal" pos="0 0 0">
            <inertial diaginertia="6.0869 5.81635 4.20915" mass="60.864" pos="0 0 0" quat="0.659267 -0.259505 -0.260945 0.655692"/>
            <geom conaffinity="0" contype="0" group="1" mesh="pedestal" pos="0.26 0.345 -0.91488" quat="0.5 0.5 -0.5 -0.5" rgba="0.2 0.2 0.2 1" type="mesh" name="pedestal_col1"/>
            <geom pos="-0.02 0 -0.29" rgba="0.2 0.2 0.2 1" size="0.18 0.3" type="cylinder" name="pedestal_col2"/>
        </body>

        <body name="robot0_link0" pos="0 0 0" quat="0.707107 0 0 0.707107">
        <inertial pos="0 0 0.05" mass="4" diaginertia="0.4 0.4 0.4" />
        <geom class="panda_viz" mesh="link0_viz"/>
        <geom class="panda_col" mesh="link0_col"/>
            <body name="robot0_link1" pos="0 0 0.333">
                <inertial pos="0 0 -0.07" mass="3" diaginertia="0.3 0.3 0.3" />
                <joint name="joint1" axis="0 0 1" limited="true" range="-2.8973 2.8973" class="panda_arm"/>
                <geom class="panda_viz" mesh="link1_viz"/>
                <geom class="panda_col" mesh="link1_col"/>
                <body name="robot0_link2" pos="0 0 0" quat="0.707107 -0.707107 0 0">
                    <inertial pos="0 -0.1 0" mass="3" diaginertia="0.3 0.3 0.3" />
                    <joint name="joint2" pos="0 0 0" axis="0 0 1" limited="true" range="-1.7628 1.7628" class="panda_arm"/>
                    <geom class="panda_viz" mesh="link2_viz"/>
                    <geom class="panda_col" mesh="link2_col"/>
                    <body name="robot0_link3" pos="0 -0.316 0" quat="0.707107 0.707107 0 0">
    <!--                <body name="robot0_link3" pos="0 -0.316 0" quat="0.500 0.500 0.500 -0.500">-->
                        <inertial pos="0.04 0 -0.05" mass="2" diaginertia="0.2 0.2 0.2" />
                        <joint name="joint3" pos="0 0 0" axis="0 0 1" limited="true" range="-0.1 0.1" class="panda_arm"/>
                        <geom class="panda_viz" mesh="link3_viz"/>
                        <geom class="panda_grey_viz" mesh="link3_dark_viz" pos="0 .001 0"/>
                        <geom class="panda_col" mesh="link3_col"/>
                        <body name="robot0_link4" pos="0.0825 0 0" quat="0.707107 0.707107 0 0">
                            <inertial pos="-0.04 0.05 0" mass="2" diaginertia="0.2 0.2 0.2" />
                            <joint name="joint4" pos="0 0 0" axis="0 0 1" limited="true" range="-2.6 -0.55" class="panda_arm"/>
                            <geom class="panda_viz" mesh="link4_viz"/>
                            <geom class="panda_grey_viz" mesh="link4_dark_viz"/>
                            <geom class="panda_col" mesh="link4_col"/>
                            <body name="robot0_link5" pos="-0.0825 0.384 0" quat="0.707107 -0.707107 0 0">
    <!--                        <body name="robot0_link5" pos="-0.0825 0.384 0" quat="0.500 -0.500 0.500 0.500">-->
                                <inertial pos="0 0 -0.15" mass="2" diaginertia="0.2 0.2 0.2" />
                                <joint name="joint5" pos="0 0 0" axis="0 0 1" limited="true" range="-0.1 0.1" class="panda_forearm"/>
                                <geom class="panda_viz" mesh="link5_viz"/>
                                <geom class="panda_grey_viz" mesh="link5_dark_viz"/>
                                <geom class="panda_col" mesh="link5_col"/>
                                <body name="robot0_link6" pos="0 0 0" quat="0.707107 0.707107 0 0">
                                    <inertial pos="0.06 0 0" mass="1.5" diaginertia="0.1 0.1 0.1" />
                                    <joint name="joint6" pos="0 0 0" axis="0 0 1" limited="true" range="-0.0175 3.7525" class="panda_forearm"/>
                                    <geom class="panda_viz" mesh="link6_viz"/>
                                    <geom class="panda_grey_viz" mesh="link6_dark_viz"/>
                                    <geom class="panda_col" mesh="link6_col"/>
                                    <body name="robot0_link7" pos="0.088 0 0" quat="0.707107 0.707107 0 0">
    <!--                                <body name="robot0_link7" pos="0.088 0 0" quat="0.653 0.653 -0.271 0.271">-->
                                        <inertial pos="0 0 0.08" mass="0.5" diaginertia="0.05 0.05 0.05" />
                                        <joint name="joint7" pos="0 0 0" axis="0 0 1" limited="true" range="-0.01 0.01" class="panda_forearm"/>
                                        <geom class="panda_viz" mesh="link7_viz" quat="0.924 0 0 -0.383" rgba=".8 .8 .82 1"/>
                                        <geom class="panda_grey_viz" mesh="link7_dark_viz" quat="0.924 0 0 -0.383" pos="0 0 -.0008"/>
                                        <geom class="panda_col" mesh="link7_col"/>
                                        <!-- End Effector -->
                                        <body name="right_hand" pos="0 0 0" quat="0.707 0 0 -0.707">
                                            <inertial pos="0 0 0" mass="0.81909" diaginertia="0.05 0.05 0.05" />
                                            <geom pos="0 0 0.107" class="panda_viz" mesh="hand_viz"/>
                                            <geom pos="0 0 0.107" class="panda_col" mesh="hand_col" />
<!--                                            <geom size="0.035 0.05" pos="0 0 0.1" type="cylinder" rgba="1 1 0 1"/>-->

<!--                                            <body name="hand" pos="0. 0 0.107" quat="-1 0 1 0">-->
                                            <body name="hand" pos="0. 0 0.17" quat="-1 0 1 0">
                                                    <site name="handv" pos="0 0 0" size="0.01" rgba='1 1 0 1' />
                                                    <site name="endEffector" pos="0.04 0 0" size="0.01" rgba='1 0 0 1' />
                                                    <body name="leftclaw" pos="0.0 0 0.0" quat="0.707107 0 0.707107 0">
                                                        <inertial pos="0 0 0.05" mass="0.1" diaginertia="0.01 0.01 0.005" />
            <!--                                            <inertial pos="0 0 0.05" mass="1.6" diaginertia="0.01 0.01 0.005" />-->
                                                        <geom name="leftclaw_it" type="mesh" user="0" conaffinity="1" contype="0" solref="0.02 1" friction="1 0.005 0.0001" condim="4" mesh="finger_vis" mass="0.1"/>
    <!--                                                    <geom name="leftclaw_it" pos="-0.022 0.03 -0.022" quat="0.707 0 0 -0.707" type="mesh" user="0" conaffinity="1" contype="0" solref="0.02 1" friction="1 0.005 0.0001" condim="4" mesh="finger_vis2" mass="0.1"/>-->
                                                        <joint name="l_close" pos="0 0 0" axis="0 1 0" type="slide" limited="true" range="0 0.05" armature="100" damping="1000" frictionloss="1.0"/>
            <!--                                            <geom name="finger1_visual" type="mesh" contype="0" conaffinity="0" group="1" mesh="finger_vis" rgba="0.499 0.499 0.499 1" />-->
                                                        <site name="leftEndEffector" pos="0. 0 0.05" size="0.005" rgba="1.0 0.0 0.0 1.0"/>
    <!--                                                    <site name="leftEndEffector" pos="0 0 0.138" size="0.005" rgba="1.0 0.0 0.0 1.0"/>-->
                                                        <body name="leftpad" pos="0 0.0085 0.056">
                                                            <inertial pos="0 0 0" quat="0 0 0 1" mass="0.01" diaginertia="0.01 0.01 0.01" />
                                                            <geom name="leftpad_geom" size="0.008 0.004 0.008" pos="0 -0.005 -0.015" type="box" user="0" solref="0.01 0.5" friction = "2 0.05 0.0001" conaffinity="1" contype="1"/>
                                                        </body>
    <!--                                                    <body name="leftpad" pos="0 0.0055 0.146">-->
    <!--                                                        <inertial pos="0 0 0" quat="0 0 0 1" mass="0.01" diaginertia="0.01 0.01 0.01" />-->
    <!--                                                        <geom name="leftpad_geom" size="0.008 0.003 0.01" pos="0 -0.005 -0.015" type="box" user="0" solref="0.01 0.5" friction = "2 0.05 0.0001" conaffinity="1" contype="1"/>-->
    <!--                                                    </body>-->
                                                    </body>
                                                    <body name="rightclaw" pos="0.0 0 0.0" quat="0.707107 0 0.707107 0">
                                                        <inertial pos="0 0 0.05" mass="0.1" diaginertia="0.01 0.01 0.005" />
            <!--                                            <inertial pos="0 0 0.05" mass="1.6" diaginertia="0.01 0.01 0.005" />-->
                                                        <geom name="rightclaw_it" quat="0 0 0 1" type="mesh" user="0" conaffinity="1" contype="0" solref="0.02 1" friction="1 0.005 0.0001" condim="4" mesh="finger_vis" mass="0.1"/>
    <!--                                                    <geom name="rightclaw_it" pos="0.022 -0.03 -0.022" quat="0.707 0 0 0.707" type="mesh" user="0" conaffinity="1" contype="0" solref="0.02 1" friction="1 0.005 0.0001" condim="4" mesh="finger_vis2" mass="0.1"/>-->
                                                        <joint name="r_close" pos="0 0 0" axis="0 1 0" type="slide" limited="true" range="-0.05 0" damping="1000" armature="100.0" frictionloss="1.0"/>
            <!--                                            <geom name="finger2_visual" quat="0 0 0 1" type="mesh" contype="0" conaffinity="0" group="1" mesh="finger_vis" rgba="0.499 0.499 0.499 1" />-->
                                                        <site name="rightEndEffector" pos="0 0 0.05" size="0.005" rgba="1.0 0.0 0.0 1.0"/>
    <!--                                                    <site name="rightEndEffector" pos="0 0 0.138" size="0.005" rgba="1.0 0.0 0.0 1.0"/>-->
                                                        <body name="rightpad" pos="0 -0.0085 0.056">
                                                            <inertial pos="0 0 0" quat="0 0 0 1" mass="0.01" diaginertia="0.01 0.01 0.01" />
                                                            <geom name="rightpad_geom" size="0.008 0.004 0.008" pos="0 0.005 -0.015" type="box" user="0" solref="0.01 0.5" friction = "2 0.05 0.0001" conaffinity="1" contype="1"/>
                                                        </body>
    <!--                                                    <body name="rightpad" pos="0 -0.0055 0.146">-->
    <!--                                                        <inertial pos="0 0 0" quat="0 0 0 1" mass="0.01" diaginertia="0.01 0.01 0.01" />-->
    <!--                                                        <geom name="rightpad_geom" size="0.008 0.003 0.01" pos="0 0.005 -0.015" type="box" user="0" solref="0.01 0.5" friction = "2 0.05 0.0001" conaffinity="1" contype="1"/>-->
    <!--                                                    </body>-->
                                                    </body>

                                                </body>
                                        </body>
                                    </body>
                                </body>
                            </body>
                        </body>
                    </body>
                </body>
            </body>
        </body>
    </body>


    <body mocap="true" name="mocap" pos="0 0 0">
        <!--For debugging, set the alpha to 1-->
<!--        <geom conaffinity="0" contype="0" pos="0 0 0" rgba="0.5 0.5 0.5 1" size="0.1 0.02 0.02" type="box"></geom>-->
        <geom conaffinity="0" contype="0" pos="0 0 0" rgba="0.0 0.5 0.5 0" size="0.03" type="sphere"></geom>
        <site name="mocap" pos="0 0 0" rgba="0.0 0.5 0.5 1" size="0.01" type="sphere"></site>
    </body>

</mujoco>
